<?xml version="1.0"?>
<robot xmlns:xacro="http://www.ros.org/wiki/xacro">
    
    <xacro:macro name="AX18" params="name parent child *p_origin *c_origin">
        <joint name="${name}" type="revolute">
            <xacro:insert_block name="c_origin"/>
            <parent link="${name}_AX18"/>
            <child link ="${child}"/>
            <axis xyz="0 0 1"/>
            <limit 
                effort="150.0" 
                velocity="12.0"
                lower="-2e16"
                upper="2e16"/>
        </joint>
        <gazebo reference="${name}">
			<provideFeedback>true</provideFeedback>
            <preserveFixedJoint>true</preserveFixedJoint>
		</gazebo>
        
        <joint name="${name}_dyn_fixed" type="fixed">
            <xacro:insert_block name="p_origin"/>
            <parent link="${parent}"/>
            <child link ="${name}_AX18"/>
        </joint>
        <gazebo reference="${name}_dyn_fixed">
			<provideFeedback>true</provideFeedback>
            <preserveFixedJoint>true</preserveFixedJoint>
		</gazebo>

        <link name="${name}_AX18">
            <inertial>
                <origin xyz="0 0 0"/>
                <mass value="0.0546"/>
                <inertia
                    ixx="1.57e-5" ixy="0" ixz="0"
                    iyy="0" iyz="0"
                    izz="0"/>
            </inertial>
            <visual>
                <geometry>
                    <!-- <box size="0.0320 0.0500 0.0400"/> -->
                    <mesh filename="package://automi_description/meshes/AX18.stl"  scale="1e-2 1e-2 1e-2"/>
                </geometry>
            </visual>
            <collision>
                <geometry>
                    <!-- <box size="0.0320 0.0500 0.0400"/> -->
                    <mesh filename="package://automi_description/meshes/AX18.stl"  scale="1e-2 1e-2 1e-2"/>
                </geometry>
            </collision>
        </link>
        <gazebo reference="${name}_AX18">
            <material>
                Gazebo/Black
            </material>
        </gazebo>

    </xacro:macro>

    <xacro:macro name="MX28" params="name parent child *p_origin *c_origin">
        <joint name="${name}" type="revolute">
            <xacro:insert_block name="c_origin"/>
            <parent link="${name}_MX28"/>
            <child link ="${child}"/>
            <axis xyz="0 0 1"/>
            <limit 
                effort="150.0" 
                velocity="12.0"
                lower="-2e16"
                upper="2e16"/>
        </joint>
        <gazebo reference="${name}">
			<provideFeedback>true</provideFeedback>
            <preserveFixedJoint>true</preserveFixedJoint>
		</gazebo>
        
        <joint name="${name}_dyn_fixed" type="fixed">
            <xacro:insert_block name="p_origin"/>
            <parent link="${parent}"/>
            <child link ="${name}_MX28"/>
        </joint>
        <gazebo reference="${name}_dyn_fixed">
			<provideFeedback>true</provideFeedback>
            <preserveFixedJoint>true</preserveFixedJoint>
		</gazebo>

        <link name="${name}_MX28">
            <inertial>
                <origin xyz="0 0 0"/>
                <mass value="0.072"/>
                <inertia
                    ixx="0" ixy="0" ixz="0"
                    iyy="0" iyz="0"
                    izz="0"/>
            </inertial>
            <visual>
                <origin xyz="0 0 0" rpy="0.0 0.0 ${PI}"/>
                <geometry>
                    <!-- <box size="0.0356 0.0506 0.0356"/> -->
                    <mesh filename="package://automi_description/meshes/MX28.stl"  scale="1e-2 1e-2 1e-2"/>
                </geometry>
            </visual>
            <collision>
                <origin xyz="0 0 0" rpy="0.0 0.0 ${PI}"/>
                <geometry>
                    <!-- <box size="0.0356 0.0506 0.0356"/> -->
                    <mesh filename="package://automi_description/meshes/MX28.stl"  scale="1e-2 1e-2 1e-2"/>
                </geometry>
            </collision>
        </link>
        <gazebo reference="${name}_MX28">
            <material>
                Gazebo/Black
            </material>
        </gazebo>
        
    </xacro:macro>

    <xacro:macro name="MX64" params="name parent child *p_origin *c_origin">
        <joint name="${name}" type="revolute">
            <xacro:insert_block name="c_origin"/>
            <parent link="${name}_MX64"/>
            <child link ="${child}"/>
            <axis xyz="0 0 1"/>
            <limit 
                effort="150.0" 
                velocity="12.0"
                lower="-2e16"
                upper="2e16"/>
        </joint>
        <gazebo reference="${name}">
			<provideFeedback>true</provideFeedback>
            <preserveFixedJoint>true</preserveFixedJoint>
		</gazebo>

        <joint name="${name}_dyn_fixed" type="fixed">
            <xacro:insert_block name="p_origin"/>
            <parent link="${parent}"/>
            <child link ="${name}_MX64"/>
        </joint>
        <gazebo reference="${name}_dyn_fixed">
			<provideFeedback>true</provideFeedback>
            <preserveFixedJoint>true</preserveFixedJoint>
		</gazebo>

        <link name="${name}_MX64">
            <inertial>
                <origin xyz="0 0 0"/>
                <mass value="0.1650"/>
                <inertia
                    ixx="0" ixy="0" ixz="0"
                    iyy="0" iyz="0"
                    izz="0"/>
            </inertial>
            <visual>
                <origin xyz="0 0 0" rpy="0.0 ${PI/2} ${PI}"/>
                <geometry>
                    <!-- <box size="0.0402 0.0611 0.0410"/> -->
                    <mesh filename="package://automi_description/meshes/MX64.stl"  scale="1e-2 1e-2 1e-2"/>
                </geometry>
            </visual>
            <collision>
                <origin xyz="0 0 0" rpy="0.0 ${PI/2} ${PI}"/>
                <geometry>
                    <!-- <box size="0.0402 0.0611 0.0410"/> -->
                    <mesh filename="package://automi_description/meshes/MX64.stl"  scale="1e-2 1e-2 1e-2"/>
                </geometry>
            </collision>
        </link>
        <gazebo reference="${name}_MX64">
            <material>
                Gazebo/Black
            </material>
        </gazebo>
        
    </xacro:macro>

</robot>